<?xml version="1.0" encoding="utf-8"?>
<mujoco><size njmax="3000" nconmax="1000"></size><option timestep="0.004"></option><default><geom condim="6" density="5" rgba="1 0 0 1" size=".05" type="sphere"></geom><joint damping=".001"></joint><motor ctrlrange="-1 1" ctrllimited="true" forcerange="-.02 .02" forcelimited="true"></motor><site size="0.032" type="sphere"></site></default><worldbody><geom name="floor" size="3.5 3.5 0.1" type="plane" condim="6" rgba="1 1 1 1" material="MatPlane"></geom><body name="robot" pos="0 0 .1"><site name="robot" pos="0 0 0"></site><camera name="vision" pos="0 0.1 .2" xyaxes="-1 0 0 0 -.4 1"></camera><joint type="free" name="robot" damping="0"></joint><geom name="robot" type="box" size=".1 .1 .05"></geom><geom name="back_bumper" type="box" pos="0 .15 0" size=".1 .01 .05"></geom><geom name="back_connector" type="box" pos="0 .125 0" size=".01 .025 .03"></geom><geom name="front_bumper" type="box" pos="0 -.165 0" size=".05 .01 .05"></geom><geom name="front_connector" type="box" pos="0 -.13 .04" size=".05 .03 .01"></geom><body name="left" pos="-.1 .1 -.05"><joint type="hinge" name="left" axis="1 0 0"></joint><geom type="cylinder" name="left" fromto="-.055 0 0 -0.005 0 0"></geom></body><body name="right" pos=".1 .1 -.05"><joint type="hinge" name="right" axis="1 0 0"></joint><geom type="cylinder" name="right" fromto="0.005 0 0 .055 0 0"></geom></body><body name="rear" pos="0 -.1 -.05"><joint name="rear" type="ball"></joint><geom name="rear"></geom></body></body><light cutoff="100" diffuse="1 1 1" dir="0 0 -1" directional="true" exponent="1" pos="0 0 0.5" specular="0 0 0" castshadow="false"></light><camera name="fixednear" pos="0 -2 2" zaxis="0 -1 1"></camera><camera name="fixedfar" pos="0 -5 5" zaxis="0 -1 1"></camera></worldbody><sensor><ballquat joint="rear" name="ballquat_rear"></ballquat><ballangvel joint="rear" name="ballangvel_rear"></ballangvel><accelerometer site="robot" name="accelerometer"></accelerometer><velocimeter site="robot" name="velocimeter"></velocimeter><gyro site="robot" name="gyro"></gyro><magnetometer site="robot" name="magnetometer"></magnetometer><subtreecom body="robot" name="subtreecom"></subtreecom><subtreelinvel body="robot" name="subtreelinvel"></subtreelinvel><subtreeangmom body="robot" name="subtreeangmom"></subtreeangmom></sensor><actuator><motor gear="1" jointinparent="left" name="left"></motor><motor gear="1" jointinparent="right" name="right"></motor></actuator><asset><texture type="skybox" builtin="gradient" rgb1="0.527 0.582 0.906" rgb2="0.1 0.1 0.35" width="800" height="800" markrgb="1 1 1" mark="random" random="0.001"></texture><texture name="texplane" builtin="checker" height="100" width="100" rgb1="0.7 0.7 0.7" rgb2="0.8 0.8 0.8" type="2d"></texture><material name="MatPlane" reflectance="0.1" shininess="0.1" specular="0.1" texrepeat="10 10" texture="texplane"></material></asset></mujoco>